#VRML_SIM R2023b utf8

EXTERNPROTO "https://raw.githubusercontent.com/cyberbotics/webots/R2023b/projects/appearances/protos/BrushedSteel.proto"
EXTERNPROTO "https://raw.githubusercontent.com/cyberbotics/webots/R2023b/projects/appearances/protos/Copper.proto"
EXTERNPROTO "https://raw.githubusercontent.com/cyberbotics/webots/R2023b/projects/appearances/protos/DamascusSteel.proto"
EXTERNPROTO "https://raw.githubusercontent.com/cyberbotics/webots/R2023b/projects/appearances/protos/HammeredCopper.proto"
EXTERNPROTO "https://raw.githubusercontent.com/cyberbotics/webots/R2023b/projects/appearances/protos/SandyGround.proto"
EXTERNPROTO "https://raw.githubusercontent.com/cyberbotics/webots/R2023b/projects/appearances/protos/SolarCell.proto"
EXTERNPROTO "https://raw.githubusercontent.com/cyberbotics/webots/R2023b/projects/objects/backgrounds/protos/TexturedBackground.proto"
EXTERNPROTO "https://raw.githubusercontent.com/cyberbotics/webots/R2023b/projects/objects/backgrounds/protos/TexturedBackgroundLight.proto"
EXTERNPROTO "https://raw.githubusercontent.com/cyberbotics/webots/R2023b/projects/objects/floors/protos/UnevenTerrain.proto"

WorldInfo {
}
Viewpoint {
  orientation 0.18185867803548508 0.07411432391041367 -0.9805276580568688 2.5331615274108454
  position 10.899822355058822 7.5204210719185305 8.615098688301462
}
TexturedBackground {
  texture "mars"
}
TexturedBackgroundLight {
  luminosity 2
}
UnevenTerrain {
  appearance SandyGround {
    colorOverride 0.5 0.5 0.4
    textureTransform TextureTransform {
      scale 50 50
    }
  }
}
Robot {
  translation -0.5249471545758287 -0.04697527193130723 3.3537696357823177
  rotation 0.8432978521248897 -0.5374056911468641 -0.006622365476855846 0.08937143759295832
  children [
    DEF body Shape {
      appearance HammeredCopper {
      }
      geometry Box {
        size 0.7 0.5 0.2
      }
    }
    Solid {
      translation 0 0 0.19
      children [
        DEF panel Shape {
          appearance SolarCell {
          }
          geometry Box {
            size 0.8 0.5 0.01
          }
        }
        Solid {
          translation 0.3 -0.19 -0.05
          children [
            Shape {
              appearance Copper {
              }
              geometry Cylinder {
                height 0.1
                radius 0.02
              }
            }
          ]
          name "solar_panel_support1"
        }
        Solid {
          translation 0.3 0.19 -0.05
          children [
            Shape {
              appearance Copper {
              }
              geometry Cylinder {
                height 0.1
                radius 0.02
              }
            }
          ]
          name "solar_panel_support2"
        }
        Solid {
          translation -0.3 0.19 -0.05
          children [
            Shape {
              appearance Copper {
              }
              geometry Cylinder {
                height 0.1
                radius 0.02
              }
            }
          ]
          name "solar_panel_support3"
        }
        Solid {
          translation -0.3 -0.19 -0.05
          children [
            Shape {
              appearance Copper {
              }
              geometry Cylinder {
                height 0.1
                radius 0.02
              }
            }
          ]
          name "solar_panel_support4"
        }
      ]
      name "solar_panel"
    }
    Solid {
      translation -0.18 -0.24 0
      children [
        SliderJoint {
          jointParameters JointParameters {
            position -4.0529997960600914e-05
            minStop -0.1
            staticFriction 1
          }
          device [
            LinearMotor {
              name "linear1_left"
              maxForce 50
            }
          ]
          endPoint Solid {
            translation -0.00017985453301283538 -0.017342787906382884 0.06001075547265197
            rotation -0.9999999928695749 8.057119204137451e-05 -8.814268504930294e-05 1.5708453179831379
            children [
              DEF cylinder1 Shape {
                appearance DamascusSteel {
                }
                geometry Cylinder {
                  height 0.09
                  radius 0.02
                }
              }
              Solid {
                translation 0 0 -0.05
                children [
                  DEF sphere1 Shape {
                    appearance BrushedSteel {
                    }
                    geometry Sphere {
                      radius 0.02
                    }
                  }
                  Solid {
                    translation 0 0.1 1.79608e-07
                    rotation -1 0 0 -1.5707953071795862
                    children [
                      DEF cylinder2 Shape {
                        appearance BrushedSteel {
                        }
                        geometry Cylinder {
                          height 0.2
                          radius 0.02
                        }
                      }
                      Solid {
                        translation 0 0 -0.11
                        children [
                          DEF sphere1 Shape {
                            appearance BrushedSteel {
                            }
                            geometry Sphere {
                              radius 0.02
                            }
                          }
                          Solid {
                            translation 0 -0.03 -9.99999e-08
                            rotation 1 0 0 1.5708
                            children [
                              DEF cylinder3 Shape {
                                appearance BrushedSteel {
                                }
                                geometry Cylinder {
                                  height 0.06
                                  radius 0.02
                                }
                              }
                              HingeJoint {
                                jointParameters HingeJointParameters {
                                  position -4.627711693683841
                                  axis 0 0 1
                                  anchor -9.51224e-05 0.00113507 0.0800056
                                }
                                device [
                                  RotationalMotor {
                                    name "wheel1_left"
                                  }
                                ]
                                endPoint Solid {
                                  translation 0.0010047044632611737 0.0014814573240437322 0.08000499999999995
                                  rotation -7.549027848812096e-07 6.888521710259739e-07 -0.9999999999994779 4.627710542015742
                                  children [
                                    DEF wheel Shape {
                                      appearance DamascusSteel {
                                      }
                                      geometry Cylinder {
                                        height 0.15
                                        radius 0.15
                                      }
                                    }
                                  ]
                                  boundingObject USE wheel
                                  physics Physics {
                                    mass 1
                                  }
                                }
                              }
                            ]
                            boundingObject USE cylinder3
                            physics DEF phy1 Physics {
                              mass 1
                            }
                          }
                        ]
                        name "solid(1)"
                        boundingObject USE sphere1
                        physics USE phy1
                      }
                    ]
                    boundingObject USE cylinder2
                    physics USE phy1
                  }
                ]
                boundingObject USE sphere1
                physics USE phy1
              }
            ]
            boundingObject USE cylinder1
            physics USE phy1
          }
        }
      ]
      name "wheel1_left_system"
      physics USE phy1
    }
    Solid {
      translation 0.18 -0.24 0
      children [
        SliderJoint {
          jointParameters JointParameters {
            position -1.4334874196480073e-05
            minStop -0.1
            staticFriction 1
          }
          device [
            LinearMotor {
              name "linear2_left"
              maxForce 50
            }
          ]
          endPoint Solid {
            translation -0.00017985453301283538 -0.017342787906382884 0.060036950596416096
            rotation -0.9999999928695749 8.057119204137451e-05 -8.814268504930294e-05 1.5708453179831379
            children [
              DEF cylinder1 Shape {
                appearance DamascusSteel {
                }
                geometry Cylinder {
                  height 0.09
                  radius 0.02
                }
              }
              Solid {
                translation 0 0 -0.05
                children [
                  DEF sphere1 Shape {
                    appearance BrushedSteel {
                    }
                    geometry Sphere {
                      radius 0.02
                    }
                  }
                  Solid {
                    translation 0 0.1 1.79608e-07
                    rotation -1 0 0 -1.5707953071795862
                    children [
                      DEF cylinder2 Shape {
                        appearance BrushedSteel {
                        }
                        geometry Cylinder {
                          height 0.2
                          radius 0.02
                        }
                      }
                      Solid {
                        translation 0 0 -0.11
                        children [
                          DEF sphere1 Shape {
                            appearance BrushedSteel {
                            }
                            geometry Sphere {
                              radius 0.02
                            }
                          }
                          Solid {
                            translation 0 -0.03 -9.99999e-08
                            rotation 1 0 0 1.5708
                            children [
                              DEF cylinder3 Shape {
                                appearance BrushedSteel {
                                }
                                geometry Cylinder {
                                  height 0.06
                                  radius 0.02
                                }
                              }
                              HingeJoint {
                                jointParameters HingeJointParameters {
                                  position 161.60576141005612
                                  axis 0 0 1
                                  anchor 0.000341778 0.000558794 0.0800055
                                }
                                device [
                                  RotationalMotor {
                                    name "wheel2_left"
                                  }
                                ]
                                endPoint Solid {
                                  translation -0.00016341696721396338 0.0008420206585510794 0.08000499999999995
                                  rotation -7.504603965265538e-07 -6.265397076811769e-07 -0.9999999999995222 1.7570554249490002
                                  children [
                                    DEF wheel Shape {
                                      appearance DamascusSteel {
                                      }
                                      geometry Cylinder {
                                        height 0.15
                                        radius 0.15
                                      }
                                    }
                                  ]
                                  boundingObject USE wheel
                                  physics Physics {
                                    mass 1
                                  }
                                }
                              }
                            ]
                            boundingObject USE cylinder3
                            physics DEF phy1 Physics {
                              mass 1
                            }
                          }
                        ]
                        name "solid(1)"
                        boundingObject USE sphere1
                        physics USE phy1
                      }
                    ]
                    boundingObject USE cylinder2
                    physics USE phy1
                  }
                ]
                boundingObject USE sphere1
                physics USE phy1
              }
            ]
            boundingObject USE cylinder1
            physics USE phy1
          }
        }
      ]
      name "wheel2_left_system"
      physics USE phy1
    }
    Solid {
      translation 0.18 0.24 0
      rotation 0 0 1 3.14159
      children [
        SliderJoint {
          jointParameters JointParameters {
            position -0.0011294858845557559
            minStop -0.1
            staticFriction 1
          }
          device [
            LinearMotor {
              name "linear2_right"
              maxForce 50
            }
          ]
          endPoint Solid {
            translation -0.00017985453301283538 -0.017342787906382884 0.05892179958605682
            rotation -0.9999999928695749 8.057119204137451e-05 -8.814268504930294e-05 1.5708453179831379
            children [
              DEF cylinder1 Shape {
                appearance DamascusSteel {
                }
                geometry Cylinder {
                  height 0.09
                  radius 0.02
                }
              }
              Solid {
                translation 0 0 -0.05
                children [
                  DEF sphere1 Shape {
                    appearance BrushedSteel {
                    }
                    geometry Sphere {
                      radius 0.02
                    }
                  }
                  Solid {
                    translation 0 0.1 1.79608e-07
                    rotation -1 0 0 -1.5707953071795862
                    children [
                      DEF cylinder2 Shape {
                        appearance BrushedSteel {
                        }
                        geometry Cylinder {
                          height 0.2
                          radius 0.02
                        }
                      }
                      Solid {
                        translation 0 0 -0.11
                        children [
                          DEF sphere1 Shape {
                            appearance BrushedSteel {
                            }
                            geometry Sphere {
                              radius 0.02
                            }
                          }
                          Solid {
                            translation 0 -0.03 -9.99999e-08
                            rotation 1 0 0 1.5708
                            children [
                              DEF cylinder3 Shape {
                                appearance BrushedSteel {
                                }
                                geometry Cylinder {
                                  height 0.06
                                  radius 0.02
                                }
                              }
                              HingeJoint {
                                jointParameters HingeJointParameters {
                                  position -244.31747762854928
                                  axis 0 0 1
                                  anchor 0.00034353 0.000611995 0.0800044
                                }
                                device [
                                  RotationalMotor {
                                    name "wheel2_right"
                                  }
                                ]
                                endPoint Solid {
                                  translation 0.0006041990086409143 3.8081632757464186e-05 0.08000499999999995
                                  rotation 0.35543059790074133 -0.9347026746916264 -4.91385045285934e-07 3.1415951189172393
                                  children [
                                    DEF wheel Shape {
                                      appearance DamascusSteel {
                                      }
                                      geometry Cylinder {
                                        height 0.15
                                        radius 0.15
                                      }
                                    }
                                  ]
                                  boundingObject USE wheel
                                  physics Physics {
                                    mass 1
                                  }
                                }
                              }
                            ]
                            boundingObject USE cylinder3
                            physics DEF phy1 Physics {
                              mass 1
                            }
                          }
                        ]
                        name "solid(1)"
                        boundingObject USE sphere1
                        physics USE phy1
                      }
                    ]
                    boundingObject USE cylinder2
                    physics USE phy1
                  }
                ]
                boundingObject USE sphere1
                physics USE phy1
              }
            ]
            boundingObject USE cylinder1
            physics USE phy1
          }
        }
      ]
      name "wheel2_right_system"
      physics USE phy1
    }
    Solid {
      translation -0.18 0.24 0
      rotation 0 0 1 3.14159
      children [
        SliderJoint {
          jointParameters JointParameters {
            position -6.227917187290257e-06
            minStop -0.1
            staticFriction 1
          }
          device [
            LinearMotor {
              name "linear1_right"
              maxForce 50
            }
          ]
          endPoint Solid {
            translation -0.00017985453301283538 -0.017342787906382884 0.06004505755342527
            rotation -0.9999999928695749 8.057119204137451e-05 -8.814268504930294e-05 1.5708453179831379
            children [
              DEF cylinder1 Shape {
                appearance DamascusSteel {
                }
                geometry Cylinder {
                  height 0.09
                  radius 0.02
                }
              }
              Solid {
                translation 0 0 -0.05
                children [
                  DEF sphere1 Shape {
                    appearance BrushedSteel {
                    }
                    geometry Sphere {
                      radius 0.02
                    }
                  }
                  Solid {
                    translation 0 0.1 1.79608e-07
                    rotation -1 0 0 -1.5707953071795862
                    children [
                      DEF cylinder2 Shape {
                        appearance BrushedSteel {
                        }
                        geometry Cylinder {
                          height 0.2
                          radius 0.02
                        }
                      }
                      Solid {
                        translation 0 0 -0.11
                        children [
                          DEF sphere1 Shape {
                            appearance BrushedSteel {
                            }
                            geometry Sphere {
                              radius 0.02
                            }
                          }
                          Solid {
                            translation 0 -0.03 -9.99999e-08
                            rotation 1 0 0 1.5708
                            children [
                              DEF cylinder3 Shape {
                                appearance BrushedSteel {
                                }
                                geometry Cylinder {
                                  height 0.06
                                  radius 0.02
                                }
                              }
                              HingeJoint {
                                jointParameters HingeJointParameters {
                                  position 3.3382664272969382
                                  axis 0 0 1
                                  anchor 0.00034338 0.000576422 0.0800045
                                }
                                device [
                                  RotationalMotor {
                                    name "wheel1_right"
                                  }
                                ]
                                endPoint Solid {
                                  translation 0.0004154568136012117 0.0011684539206024821 0.08000499999999995
                                  rotation -0.9951687564696966 -0.0981791533108123 1.3152954219000195e-06 3.1415930022025242
                                  children [
                                    DEF wheel Shape {
                                      appearance DamascusSteel {
                                      }
                                      geometry Cylinder {
                                        height 0.15
                                        radius 0.15
                                      }
                                    }
                                  ]
                                  boundingObject USE wheel
                                  physics Physics {
                                    mass 1
                                  }
                                }
                              }
                            ]
                            boundingObject USE cylinder3
                            physics DEF phy1 Physics {
                              mass 1
                            }
                          }
                        ]
                        name "solid(1)"
                        boundingObject USE sphere1
                        physics USE phy1
                      }
                    ]
                    boundingObject USE cylinder2
                    physics USE phy1
                  }
                ]
                boundingObject USE sphere1
                physics USE phy1
              }
            ]
            boundingObject USE cylinder1
            physics USE phy1
          }
        }
      ]
      name "wheel1_right_system"
      physics USE phy1
    }
  ]
  boundingObject USE body
  physics DEF phy Physics {
    mass 1
  }
  controller "Rover_Controller"
}
